
*** Starting uWSGI 2.0.17.1 (64bit) on [Tue Aug 28 14:22:20 2018] ***
compiled with version: 4.8.5 20150623 (Red Hat 4.8.5-16) on 27 August 2018 07:28:24
os: Linux-3.10.0-693.2.2.el7.x86_64 #1 SMP Tue Sep 12 22:26:13 UTC 2017
nodename: izm5e47p6szixv6rgotzl2z
machine: x86_64
clock source: unix
pcre jit disabled
detected number of CPU cores: 1
current working directory: /data/cycle/script
writing pidfile to /data/cycle/script/uwsgi.pid
detected binary path: /usr/local/bin/uwsgi
*** WARNING: you are running uWSGI as root !!! (use the --uid flag) *** 
chdir() to /data/cycle/
your processes number limit is 1879
your memory page size is 4096 bytes
detected max file descriptor number: 65535
building mime-types dictionary from file /etc/mime.types...0 entry found
lock engine: pthread robust mutexes
thunder lock: enabled
probably another instance of uWSGI is running on the same address (127.0.0.1:8001).
bind(): Address already in use [core/socket.c line 769]
Tue Aug 28 14:22:43 2018 - uWSGI worker 1 screams: UAAAAAAH my master disconnected: i will kill myself !!!
*** Starting uWSGI 2.0.17.1 (64bit) on [Tue Aug 28 14:22:47 2018] ***
compiled with version: 4.8.5 20150623 (Red Hat 4.8.5-16) on 27 August 2018 07:28:24
os: Linux-3.10.0-693.2.2.el7.x86_64 #1 SMP Tue Sep 12 22:26:13 UTC 2017
nodename: izm5e47p6szixv6rgotzl2z
machine: x86_64
clock source: unix
pcre jit disabled
detected number of CPU cores: 1
current working directory: /data/cycle/script
writing pidfile to /data/cycle/script/uwsgi.pid
detected binary path: /usr/local/bin/uwsgi
*** WARNING: you are running uWSGI as root !!! (use the --uid flag) *** 
chdir() to /data/cycle/
your processes number limit is 1879
your memory page size is 4096 bytes
detected max file descriptor number: 65535
building mime-types dictionary from file /etc/mime.types...0 entry found
lock engine: pthread robust mutexes
thunder lock: enabled
uwsgi socket 0 bound to TCP address 127.0.0.1:8001 fd 3
*** WARNING: you are running uWSGI as root !!! (use the --uid flag) *** 
Python version: 3.6.5 (default, Jul 31 2018, 15:09:54)  [GCC 4.8.5 20150623 (Red Hat 4.8.5-16)]
Python main interpreter initialized at 0x264d950
*** WARNING: you are running uWSGI as root !!! (use the --uid flag) *** 
python threads support enabled
your server socket listen backlog is limited to 100 connections
your mercy for graceful operations on workers is 60 seconds
mapped 162224 bytes (158 KB) for 1 cores
*** Operational MODE: single process ***
00:16:3e:08:f3:70
WSGI app 0 (mountpoint='') ready in 0 seconds on interpreter 0x264d950 pid: 789 (default app)
*** WARNING: you are running uWSGI as root !!! (use the --uid flag) *** 
*** uWSGI is running in multiple interpreter mode ***
spawned uWSGI master process (pid: 789)
spawned uWSGI worker 1 (pid: 791, cores: 1)
[pid: 791|app: 0|req: 1/1] 122.200.85.2 () {44 vars in 842 bytes} [Tue Aug 28 14:45:20 2018] GET /admin => generated 0 bytes in 29 msecs (HTTP/1.1 301) 3 headers in 112 bytes (1 switches on core 0)
[pid: 791|app: 0|req: 2/2] 122.200.85.2 () {44 vars in 844 bytes} [Tue Aug 28 14:45:20 2018] GET /admin/ => generated 0 bytes in 20 msecs (HTTP/1.1 302) 7 headers in 265 bytes (1 switches on core 0)
[pid: 791|app: 0|req: 3/3] 122.200.85.2 () {44 vars in 881 bytes} [Tue Aug 28 14:45:20 2018] GET /admin/login/?next=/admin/ => generated 1857 bytes in 133 msecs (HTTP/1.1 200) 7 headers in 381 bytes (1 switches on core 0)
[pid: 791|app: -1|req: -1/4] 122.200.85.2 () {44 vars in 842 bytes} [Tue Aug 28 14:45:20 2018] GET /static/admin/css/base.css => generated 16106 bytes in 0 msecs via sendfile() (HTTP/1.1 200) 2 headers in 88 bytes (0 switches on core 0)
[pid: 791|app: -1|req: -1/5] 122.200.85.2 () {44 vars in 844 bytes} [Tue Aug 28 14:45:20 2018] GET /static/admin/css/login.css => generated 1203 bytes in 0 msecs via sendfile() (HTTP/1.1 200) 2 headers in 87 bytes (0 switches on core 0)
[pid: 791|app: -1|req: -1/6] 122.200.85.2 () {44 vars in 854 bytes} [Tue Aug 28 14:45:20 2018] GET /static/admin/css/responsive.css => generated 17894 bytes in 0 msecs via sendfile() (HTTP/1.1 200) 2 headers in 88 bytes (0 switches on core 0)
[pid: 791|app: -1|req: -1/7] 122.200.85.2 () {44 vars in 844 bytes} [Tue Aug 28 14:45:20 2018] GET /static/admin/css/fonts.css => generated 423 bytes in 0 msecs via sendfile() (HTTP/1.1 200) 2 headers in 86 bytes (0 switches on core 0)
[pid: 791|app: -1|req: -1/8] 122.200.85.2 () {46 vars in 905 bytes} [Tue Aug 28 14:45:20 2018] GET /static/admin/fonts/Roboto-Regular-webfont.woff => generated 80304 bytes in 0 msecs via sendfile() (HTTP/1.1 200) 2 headers in 88 bytes (0 switches on core 0)
[pid: 791|app: -1|req: -1/9] 122.200.85.2 () {46 vars in 901 bytes} [Tue Aug 28 14:45:20 2018] GET /static/admin/fonts/Roboto-Light-webfont.woff => generated 81348 bytes in 0 msecs via sendfile() (HTTP/1.1 200) 2 headers in 88 bytes (0 switches on core 0)
Not Found: /
[pid: 791|app: 0|req: 4/10] 122.200.85.2 () {44 vars in 752 bytes} [Tue Aug 28 14:45:51 2018] GET / => generated 2285 bytes in 4 msecs (HTTP/1.1 404) 3 headers in 102 bytes (1 switches on core 0)
[pid: 791|app: 0|req: 5/11] 122.200.85.2 () {44 vars in 764 bytes} [Tue Aug 28 14:45:59 2018] GET /admin/ => generated 0 bytes in 1 msecs (HTTP/1.1 302) 7 headers in 265 bytes (1 switches on core 0)
[pid: 791|app: 0|req: 6/12] 122.200.85.2 () {44 vars in 801 bytes} [Tue Aug 28 14:45:59 2018] GET /admin/login/?next=/admin/ => generated 1857 bytes in 14 msecs (HTTP/1.1 200) 7 headers in 381 bytes (1 switches on core 0)
[pid: 791|app: -1|req: -1/13] 122.200.85.2 () {46 vars in 856 bytes} [Tue Aug 28 14:45:59 2018] GET /static/admin/css/base.css => generated 16106 bytes in 0 msecs via sendfile() (HTTP/1.1 200) 2 headers in 88 bytes (0 switches on core 0)
[pid: 791|app: -1|req: -1/14] 122.200.85.2 () {46 vars in 858 bytes} [Tue Aug 28 14:45:59 2018] GET /static/admin/css/login.css => generated 1203 bytes in 0 msecs via sendfile() (HTTP/1.1 200) 2 headers in 87 bytes (0 switches on core 0)
[pid: 791|app: -1|req: -1/15] 122.200.85.2 () {46 vars in 868 bytes} [Tue Aug 28 14:45:59 2018] GET /static/admin/css/responsive.css => generated 17894 bytes in 0 msecs via sendfile() (HTTP/1.1 200) 2 headers in 88 bytes (0 switches on core 0)
[pid: 791|app: -1|req: -1/16] 122.200.85.2 () {46 vars in 858 bytes} [Tue Aug 28 14:45:59 2018] GET /static/admin/css/fonts.css => generated 423 bytes in 0 msecs via sendfile() (HTTP/1.1 200) 2 headers in 86 bytes (0 switches on core 0)
[pid: 791|app: -1|req: -1/17] 122.200.85.2 () {48 vars in 924 bytes} [Tue Aug 28 14:45:59 2018] GET /static/admin/fonts/Roboto-Regular-webfont.woff => generated 80304 bytes in 0 msecs via sendfile() (HTTP/1.1 200) 2 headers in 88 bytes (0 switches on core 0)
[pid: 791|app: -1|req: -1/18] 122.200.85.2 () {48 vars in 920 bytes} [Tue Aug 28 14:45:59 2018] GET /static/admin/fonts/Roboto-Light-webfont.woff => generated 81348 bytes in 0 msecs via sendfile() (HTTP/1.1 200) 2 headers in 88 bytes (0 switches on core 0)
Internal Server Error: /admin/login/
Traceback (most recent call last):
  File "/usr/local/lib/python3.6/site-packages/pymysql/connections.py", line 582, in connect
    **kwargs)
  File "/usr/local/lib/python3.6/socket.py", line 724, in create_connection
    raise err
  File "/usr/local/lib/python3.6/socket.py", line 713, in create_connection
    sock.connect(sa)
ConnectionRefusedError: [Errno 111] Connection refused

During handling of the above exception, another exception occurred:

Traceback (most recent call last):
  File "/usr/local/lib/python3.6/site-packages/django/db/backends/base/base.py", line 216, in ensure_connection
    self.connect()
  File "/usr/local/lib/python3.6/site-packages/django/db/backends/base/base.py", line 194, in connect
    self.connection = self.get_new_connection(conn_params)
  File "/usr/local/lib/python3.6/site-packages/django/db/backends/mysql/base.py", line 234, in get_new_connection
    return Database.connect(**conn_params)
  File "/usr/local/lib/python3.6/site-packages/pymysql/__init__.py", line 94, in Connect
    return Connection(*args, **kwargs)
  File "/usr/local/lib/python3.6/site-packages/pymysql/connections.py", line 327, in __init__
    self.connect()
  File "/usr/local/lib/python3.6/site-packages/pymysql/connections.py", line 629, in connect
    raise exc
pymysql.err.OperationalError: (2003, "Can't connect to MySQL server on '127.0.0.1' ([Errno 111] Connection refused)")

The above exception was the direct cause of the following exception:

Traceback (most recent call last):
  File "/usr/local/lib/python3.6/site-packages/django/core/handlers/exception.py", line 35, in inner
    response = get_response(request)
  File "/usr/local/lib/python3.6/site-packages/django/core/handlers/base.py", line 128, in _get_response
    response = self.process_exception_by_middleware(e, request)
  File "/usr/local/lib/python3.6/site-packages/django/core/handlers/base.py", line 126, in _get_response
    response = wrapped_callback(request, *callback_args, **callback_kwargs)
  File "/usr/local/lib/python3.6/site-packages/django/views/decorators/cache.py", line 44, in _wrapped_view_func
    response = view_func(request, *args, **kwargs)
  File "/usr/local/lib/python3.6/site-packages/django/contrib/admin/sites.py", line 398, in login
    return LoginView.as_view(**defaults)(request)
  File "/usr/local/lib/python3.6/site-packages/django/views/generic/base.py", line 69, in view
    return self.dispatch(request, *args, **kwargs)
  File "/usr/local/lib/python3.6/site-packages/django/utils/decorators.py", line 62, in _wrapper
    return bound_func(*args, **kwargs)
  File "/usr/local/lib/python3.6/site-packages/django/views/decorators/debug.py", line 76, in sensitive_post_parameters_wrapper
    return view(request, *args, **kwargs)
  File "/usr/local/lib/python3.6/site-packages/django/utils/decorators.py", line 58, in bound_func
    return func.__get__(self, type(self))(*args2, **kwargs2)
  File "/usr/local/lib/python3.6/site-packages/django/utils/decorators.py", line 62, in _wrapper
    return bound_func(*args, **kwargs)
  File "/usr/local/lib/python3.6/site-packages/django/utils/decorators.py", line 142, in _wrapped_view
    response = view_func(request, *args, **kwargs)
  File "/usr/local/lib/python3.6/site-packages/django/utils/decorators.py", line 58, in bound_func
    return func.__get__(self, type(self))(*args2, **kwargs2)
  File "/usr/local/lib/python3.6/site-packages/django/utils/decorators.py", line 62, in _wrapper
    return bound_func(*args, **kwargs)
  File "/usr/local/lib/python3.6/site-packages/django/views/decorators/cache.py", line 44, in _wrapped_view_func
    response = view_func(request, *args, **kwargs)
  File "/usr/local/lib/python3.6/site-packages/django/utils/decorators.py", line 58, in bound_func
    return func.__get__(self, type(self))(*args2, **kwargs2)
  File "/usr/local/lib/python3.6/site-packages/django/contrib/auth/views.py", line 66, in dispatch
    return super().dispatch(request, *args, **kwargs)
  File "/usr/local/lib/python3.6/site-packages/django/views/generic/base.py", line 89, in dispatch
    return handler(request, *args, **kwargs)
  File "/usr/local/lib/python3.6/site-packages/django/views/generic/edit.py", line 141, in post
    if form.is_valid():
  File "/usr/local/lib/python3.6/site-packages/django/forms/forms.py", line 179, in is_valid
    return self.is_bound and not self.errors
  File "/usr/local/lib/python3.6/site-packages/django/forms/forms.py", line 174, in errors
    self.full_clean()
  File "/usr/local/lib/python3.6/site-packages/django/forms/forms.py", line 377, in full_clean
    self._clean_form()
  File "/usr/local/lib/python3.6/site-packages/django/forms/forms.py", line 404, in _clean_form
    cleaned_data = self.clean()
  File "/usr/local/lib/python3.6/site-packages/django/contrib/auth/forms.py", line 195, in clean
    self.user_cache = authenticate(self.request, username=username, password=password)
  File "/usr/local/lib/python3.6/site-packages/django/contrib/auth/__init__.py", line 70, in authenticate
    user = _authenticate_with_backend(backend, backend_path, request, credentials)
  File "/usr/local/lib/python3.6/site-packages/django/contrib/auth/__init__.py", line 116, in _authenticate_with_backend
    return backend.authenticate(*args, **credentials)
  File "/usr/local/lib/python3.6/site-packages/django/contrib/auth/backends.py", line 16, in authenticate
    user = UserModel._default_manager.get_by_natural_key(username)
  File "/usr/local/lib/python3.6/site-packages/django/contrib/auth/base_user.py", line 44, in get_by_natural_key
    return self.get(**{self.model.USERNAME_FIELD: username})
  File "/usr/local/lib/python3.6/site-packages/django/db/models/manager.py", line 82, in manager_method
    return getattr(self.get_queryset(), name)(*args, **kwargs)
  File "/usr/local/lib/python3.6/site-packages/django/db/models/query.py", line 397, in get
    num = len(clone)
  File "/usr/local/lib/python3.6/site-packages/django/db/models/query.py", line 254, in __len__
    self._fetch_all()
  File "/usr/local/lib/python3.6/site-packages/django/db/models/query.py", line 1179, in _fetch_all
    self._result_cache = list(self._iterable_class(self))
  File "/usr/local/lib/python3.6/site-packages/django/db/models/query.py", line 53, in __iter__
    results = compiler.execute_sql(chunked_fetch=self.chunked_fetch, chunk_size=self.chunk_size)
  File "/usr/local/lib/python3.6/site-packages/django/db/models/sql/compiler.py", line 1055, in execute_sql
    sql, params = self.as_sql()
  File "/usr/local/lib/python3.6/site-packages/django/db/models/sql/compiler.py", line 461, in as_sql
    where, w_params = self.compile(self.where) if self.where is not None else ("", [])
  File "/usr/local/lib/python3.6/site-packages/django/db/models/sql/compiler.py", line 393, in compile
    sql, params = node.as_sql(self, self.connection)
  File "/usr/local/lib/python3.6/site-packages/django/db/models/sql/where.py", line 80, in as_sql
    sql, params = compiler.compile(child)
  File "/usr/local/lib/python3.6/site-packages/django/db/models/sql/compiler.py", line 393, in compile
    sql, params = node.as_sql(self, self.connection)
  File "/usr/local/lib/python3.6/site-packages/django/db/models/lookups.py", line 160, in as_sql
    lhs_sql, params = self.process_lhs(compiler, connection)
  File "/usr/local/lib/python3.6/site-packages/django/db/models/lookups.py", line 153, in process_lhs
    db_type = self.lhs.output_field.db_type(connection=connection)
  File "/usr/local/lib/python3.6/site-packages/django/db/models/fields/__init__.py", line 648, in db_type
    return connection.data_types[self.get_internal_type()] % data
  File "/usr/local/lib/python3.6/site-packages/django/utils/functional.py", line 36, in __get__
    res = instance.__dict__[self.name] = self.func(instance)
  File "/usr/local/lib/python3.6/site-packages/django/db/backends/mysql/base.py", line 133, in data_types
    if self.features.supports_microsecond_precision:
  File "/usr/local/lib/python3.6/site-packages/django/utils/functional.py", line 36, in __get__
    res = instance.__dict__[self.name] = self.func(instance)
  File "/usr/local/lib/python3.6/site-packages/django/db/backends/mysql/features.py", line 65, in supports_microsecond_precision
    return self.connection.mysql_version >= (5, 6, 4)
  File "/usr/local/lib/python3.6/site-packages/django/utils/functional.py", line 36, in __get__
    res = instance.__dict__[self.name] = self.func(instance)
  File "/usr/local/lib/python3.6/site-packages/django/db/backends/mysql/base.py", line 343, in mysql_version
    with self.temporary_connection() as cursor:
  File "/usr/local/lib/python3.6/contextlib.py", line 81, in __enter__
    return next(self.gen)
  File "/usr/local/lib/python3.6/site-packages/django/db/backends/base/base.py", line 576, in temporary_connection
    cursor = self.cursor()
  File "/usr/local/lib/python3.6/site-packages/django/db/backends/base/base.py", line 255, in cursor
    return self._cursor()
  File "/usr/local/lib/python3.6/site-packages/django/db/backends/base/base.py", line 232, in _cursor
    self.ensure_connection()
  File "/usr/local/lib/python3.6/site-packages/django/db/backends/base/base.py", line 216, in ensure_connection
    self.connect()
  File "/usr/local/lib/python3.6/site-packages/django/db/utils.py", line 89, in __exit__
    raise dj_exc_value.with_traceback(traceback) from exc_value
  File "/usr/local/lib/python3.6/site-packages/django/db/backends/base/base.py", line 216, in ensure_connection
    self.connect()
  File "/usr/local/lib/python3.6/site-packages/django/db/backends/base/base.py", line 194, in connect
    self.connection = self.get_new_connection(conn_params)
  File "/usr/local/lib/python3.6/site-packages/django/db/backends/mysql/base.py", line 234, in get_new_connection
    return Database.connect(**conn_params)
  File "/usr/local/lib/python3.6/site-packages/pymysql/__init__.py", line 94, in Connect
    return Connection(*args, **kwargs)
  File "/usr/local/lib/python3.6/site-packages/pymysql/connections.py", line 327, in __init__
    self.connect()
  File "/usr/local/lib/python3.6/site-packages/pymysql/connections.py", line 629, in connect
    raise exc
django.db.utils.OperationalError: (2003, "Can't connect to MySQL server on '127.0.0.1' ([Errno 111] Connection refused)")
[pid: 791|app: 0|req: 7/19] 122.200.85.2 () {56 vars in 1145 bytes} [Tue Aug 28 14:46:02 2018] POST /admin/login/?next=/admin/ => generated 370680 bytes in 155 msecs (HTTP/1.1 500) 4 headers in 130 bytes (1 switches on core 0)
<<<<<<< HEAD
Tue Aug 28 15:00:44 2018 - uWSGI worker 1 screams: UAAAAAAH my master disconnected: i will kill myself !!!
*** Starting uWSGI 2.0.17.1 (64bit) on [Tue Aug 28 15:00:57 2018] ***
compiled with version: 4.8.5 20150623 (Red Hat 4.8.5-16) on 27 August 2018 07:28:24
os: Linux-3.10.0-693.2.2.el7.x86_64 #1 SMP Tue Sep 12 22:26:13 UTC 2017
nodename: izm5e47p6szixv6rgotzl2z
machine: x86_64
clock source: unix
pcre jit disabled
detected number of CPU cores: 1
current working directory: /data/cycle
writing pidfile to /data/cycle/script/uwsgi.pid
detected binary path: /usr/local/bin/uwsgi
*** WARNING: you are running uWSGI as root !!! (use the --uid flag) *** 
chdir() to /data/cycle/
your processes number limit is 1879
your memory page size is 4096 bytes
detected max file descriptor number: 65535
building mime-types dictionary from file /etc/mime.types...0 entry found
lock engine: pthread robust mutexes
thunder lock: enabled
uwsgi socket 0 bound to TCP address 127.0.0.1:8001 fd 3
*** WARNING: you are running uWSGI as root !!! (use the --uid flag) *** 
Python version: 3.6.5 (default, Jul 31 2018, 15:09:54)  [GCC 4.8.5 20150623 (Red Hat 4.8.5-16)]
Python main interpreter initialized at 0x176f950
*** WARNING: you are running uWSGI as root !!! (use the --uid flag) *** 
python threads support enabled
your server socket listen backlog is limited to 100 connections
your mercy for graceful operations on workers is 60 seconds
mapped 162224 bytes (158 KB) for 1 cores
*** Operational MODE: single process ***
Traceback (most recent call last):
  File "./cycle/wsgi.py", line 16, in <module>
    application = get_wsgi_application()
  File "/usr/local/lib/python3.6/site-packages/django/core/wsgi.py", line 12, in get_wsgi_application
    django.setup(set_prefix=False)
  File "/usr/local/lib/python3.6/site-packages/django/__init__.py", line 24, in setup
    apps.populate(settings.INSTALLED_APPS)
  File "/usr/local/lib/python3.6/site-packages/django/apps/registry.py", line 120, in populate
    app_config.ready()
  File "/usr/local/lib/python3.6/site-packages/xadmin/apps.py", line 14, in ready
    self.module.autodiscover()
  File "/usr/local/lib/python3.6/site-packages/xadmin/__init__.py", line 49, in autodiscover
    register_builtin_plugins(site)
  File "/usr/local/lib/python3.6/site-packages/xadmin/plugins/__init__.py", line 41, in register_builtin_plugins
    [import_module('xadmin.plugins.%s' % plugin) for plugin in PLUGINS if plugin not in exclude_plugins]
  File "/usr/local/lib/python3.6/site-packages/xadmin/plugins/__init__.py", line 41, in <listcomp>
    [import_module('xadmin.plugins.%s' % plugin) for plugin in PLUGINS if plugin not in exclude_plugins]
  File "/usr/local/lib/python3.6/importlib/__init__.py", line 126, in import_module
    return _bootstrap._gcd_import(name[level:], package, level)
  File "/usr/local/lib/python3.6/site-packages/xadmin/plugins/themes.py", line 3, in <module>
    import httplib2
  File "/usr/local/lib/python3.6/site-packages/httplib2/__init__.py", line 51, in <module>
    import ssl
  File "/usr/local/lib/python3.6/ssl.py", line 101, in <module>
    import _ssl             # if we can't import it, let the error propagate
ModuleNotFoundError: No module named '_ssl'
unable to load app 0 (mountpoint='') (callable not found or import error)
*** no app loaded. going in full dynamic mode ***
*** WARNING: you are running uWSGI as root !!! (use the --uid flag) *** 
*** uWSGI is running in multiple interpreter mode ***
spawned uWSGI master process (pid: 2959)
spawned uWSGI worker 1 (pid: 2961, cores: 1)
Tue Aug 28 15:08:17 2018 - uWSGI worker 1 screams: UAAAAAAH my master disconnected: i will kill myself !!!
*** Starting uWSGI 2.0.17.1 (64bit) on [Tue Aug 28 15:13:22 2018] ***
compiled with version: 4.8.5 20150623 (Red Hat 4.8.5-16) on 27 August 2018 07:28:24
os: Linux-3.10.0-693.2.2.el7.x86_64 #1 SMP Tue Sep 12 22:26:13 UTC 2017
nodename: izm5e47p6szixv6rgotzl2z
machine: x86_64
clock source: unix
pcre jit disabled
detected number of CPU cores: 1
current working directory: /data/cycle
writing pidfile to /data/cycle/script/uwsgi.pid
detected binary path: /usr/local/bin/uwsgi
*** WARNING: you are running uWSGI as root !!! (use the --uid flag) *** 
chdir() to /data/cycle/
your processes number limit is 1879
your memory page size is 4096 bytes
detected max file descriptor number: 65535
building mime-types dictionary from file /etc/mime.types...0 entry found
lock engine: pthread robust mutexes
thunder lock: enabled
uwsgi socket 0 bound to TCP address 127.0.0.1:8001 fd 3
*** WARNING: you are running uWSGI as root !!! (use the --uid flag) *** 
Python version: 3.6.5 (default, Jul 31 2018, 15:09:54)  [GCC 4.8.5 20150623 (Red Hat 4.8.5-16)]
Python main interpreter initialized at 0x282b950
*** WARNING: you are running uWSGI as root !!! (use the --uid flag) *** 
python threads support enabled
your server socket listen backlog is limited to 100 connections
your mercy for graceful operations on workers is 60 seconds
mapped 162224 bytes (158 KB) for 1 cores
*** Operational MODE: single process ***
Traceback (most recent call last):
  File "./cycle/wsgi.py", line 16, in <module>
    application = get_wsgi_application()
  File "/usr/local/lib/python3.6/site-packages/django/core/wsgi.py", line 12, in get_wsgi_application
    django.setup(set_prefix=False)
  File "/usr/local/lib/python3.6/site-packages/django/__init__.py", line 24, in setup
    apps.populate(settings.INSTALLED_APPS)
  File "/usr/local/lib/python3.6/site-packages/django/apps/registry.py", line 120, in populate
    app_config.ready()
  File "/usr/local/lib/python3.6/site-packages/xadmin/apps.py", line 14, in ready
    self.module.autodiscover()
  File "/usr/local/lib/python3.6/site-packages/xadmin/__init__.py", line 49, in autodiscover
    register_builtin_plugins(site)
  File "/usr/local/lib/python3.6/site-packages/xadmin/plugins/__init__.py", line 41, in register_builtin_plugins
    [import_module('xadmin.plugins.%s' % plugin) for plugin in PLUGINS if plugin not in exclude_plugins]
  File "/usr/local/lib/python3.6/site-packages/xadmin/plugins/__init__.py", line 41, in <listcomp>
    [import_module('xadmin.plugins.%s' % plugin) for plugin in PLUGINS if plugin not in exclude_plugins]
  File "/usr/local/lib/python3.6/importlib/__init__.py", line 126, in import_module
    return _bootstrap._gcd_import(name[level:], package, level)
  File "/usr/local/lib/python3.6/site-packages/xadmin/plugins/themes.py", line 3, in <module>
    import httplib2
  File "/usr/local/lib/python3.6/site-packages/httplib2/__init__.py", line 51, in <module>
    import ssl
  File "/usr/local/lib/python3.6/ssl.py", line 101, in <module>
    import _ssl             # if we can't import it, let the error propagate
ModuleNotFoundError: No module named '_ssl'
unable to load app 0 (mountpoint='') (callable not found or import error)
*** no app loaded. going in full dynamic mode ***
*** WARNING: you are running uWSGI as root !!! (use the --uid flag) *** 
*** uWSGI is running in multiple interpreter mode ***
spawned uWSGI master process (pid: 5025)
spawned uWSGI worker 1 (pid: 5027, cores: 1)
*** Starting uWSGI 2.0.17.1 (64bit) on [Tue Aug 28 15:16:15 2018] ***
compiled with version: 4.8.5 20150623 (Red Hat 4.8.5-16) on 27 August 2018 07:28:24
os: Linux-3.10.0-693.2.2.el7.x86_64 #1 SMP Tue Sep 12 22:26:13 UTC 2017
nodename: izm5e47p6szixv6rgotzl2z
machine: x86_64
clock source: unix
pcre jit disabled
detected number of CPU cores: 1
current working directory: /data/cycle
writing pidfile to /data/cycle/script/uwsgi.pid
detected binary path: /usr/local/bin/uwsgi
*** WARNING: you are running uWSGI as root !!! (use the --uid flag) *** 
chdir() to /data/cycle/
your processes number limit is 1879
your memory page size is 4096 bytes
detected max file descriptor number: 65535
building mime-types dictionary from file /etc/mime.types...0 entry found
lock engine: pthread robust mutexes
thunder lock: enabled
probably another instance of uWSGI is running on the same address (127.0.0.1:8001).
bind(): Address already in use [core/socket.c line 769]
Tue Aug 28 15:16:38 2018 - uWSGI worker 1 screams: UAAAAAAH my master disconnected: i will kill myself !!!
*** Starting uWSGI 2.0.17.1 (64bit) on [Tue Aug 28 15:16:41 2018] ***
compiled with version: 4.8.5 20150623 (Red Hat 4.8.5-16) on 27 August 2018 07:28:24
os: Linux-3.10.0-693.2.2.el7.x86_64 #1 SMP Tue Sep 12 22:26:13 UTC 2017
nodename: izm5e47p6szixv6rgotzl2z
machine: x86_64
clock source: unix
pcre jit disabled
detected number of CPU cores: 1
current working directory: /data/cycle
writing pidfile to /data/cycle/script/uwsgi.pid
detected binary path: /usr/local/bin/uwsgi
*** WARNING: you are running uWSGI as root !!! (use the --uid flag) *** 
chdir() to /data/cycle/
your processes number limit is 1879
your memory page size is 4096 bytes
detected max file descriptor number: 65535
building mime-types dictionary from file /etc/mime.types...0 entry found
lock engine: pthread robust mutexes
thunder lock: enabled
uwsgi socket 0 bound to TCP address 127.0.0.1:8001 fd 3
*** WARNING: you are running uWSGI as root !!! (use the --uid flag) *** 
Python version: 3.6.5 (default, Jul 31 2018, 15:09:54)  [GCC 4.8.5 20150623 (Red Hat 4.8.5-16)]
Python main interpreter initialized at 0x260a950
*** WARNING: you are running uWSGI as root !!! (use the --uid flag) *** 
python threads support enabled
your server socket listen backlog is limited to 100 connections
your mercy for graceful operations on workers is 60 seconds
mapped 162224 bytes (158 KB) for 1 cores
*** Operational MODE: single process ***
Traceback (most recent call last):
  File "./cycle/wsgi.py", line 16, in <module>
    application = get_wsgi_application()
  File "/usr/local/lib/python3.6/site-packages/django/core/wsgi.py", line 12, in get_wsgi_application
    django.setup(set_prefix=False)
  File "/usr/local/lib/python3.6/site-packages/django/__init__.py", line 24, in setup
    apps.populate(settings.INSTALLED_APPS)
  File "/usr/local/lib/python3.6/site-packages/django/apps/registry.py", line 120, in populate
    app_config.ready()
  File "/usr/local/lib/python3.6/site-packages/xadmin/apps.py", line 14, in ready
    self.module.autodiscover()
  File "/usr/local/lib/python3.6/site-packages/xadmin/__init__.py", line 49, in autodiscover
    register_builtin_plugins(site)
  File "/usr/local/lib/python3.6/site-packages/xadmin/plugins/__init__.py", line 41, in register_builtin_plugins
    [import_module('xadmin.plugins.%s' % plugin) for plugin in PLUGINS if plugin not in exclude_plugins]
  File "/usr/local/lib/python3.6/site-packages/xadmin/plugins/__init__.py", line 41, in <listcomp>
    [import_module('xadmin.plugins.%s' % plugin) for plugin in PLUGINS if plugin not in exclude_plugins]
  File "/usr/local/lib/python3.6/importlib/__init__.py", line 126, in import_module
    return _bootstrap._gcd_import(name[level:], package, level)
  File "/usr/local/lib/python3.6/site-packages/xadmin/plugins/themes.py", line 3, in <module>
    import httplib2
  File "/usr/local/lib/python3.6/site-packages/httplib2/__init__.py", line 51, in <module>
    import ssl
  File "/usr/local/lib/python3.6/ssl.py", line 101, in <module>
    import _ssl             # if we can't import it, let the error propagate
ModuleNotFoundError: No module named '_ssl'
unable to load app 0 (mountpoint='') (callable not found or import error)
*** no app loaded. going in full dynamic mode ***
*** WARNING: you are running uWSGI as root !!! (use the --uid flag) *** 
*** uWSGI is running in multiple interpreter mode ***
spawned uWSGI master process (pid: 5318)
spawned uWSGI worker 1 (pid: 5321, cores: 1)
*** Starting uWSGI 2.0.17.1 (64bit) on [Tue Aug 28 15:41:03 2018] ***
compiled with version: 4.8.5 20150623 (Red Hat 4.8.5-16) on 27 August 2018 07:28:24
os: Linux-3.10.0-693.2.2.el7.x86_64 #1 SMP Tue Sep 12 22:26:13 UTC 2017
nodename: izm5e47p6szixv6rgotzl2z
machine: x86_64
clock source: unix
pcre jit disabled
detected number of CPU cores: 1
current working directory: /data/cycle
writing pidfile to /data/cycle/script/uwsgi.pid
detected binary path: /usr/local/bin/uwsgi
*** WARNING: you are running uWSGI as root !!! (use the --uid flag) *** 
chdir() to /data/cycle/
your processes number limit is 1879
your memory page size is 4096 bytes
detected max file descriptor number: 65535
building mime-types dictionary from file /etc/mime.types...0 entry found
lock engine: pthread robust mutexes
thunder lock: enabled
probably another instance of uWSGI is running on the same address (127.0.0.1:8001).
bind(): Address already in use [core/socket.c line 769]
Tue Aug 28 15:41:29 2018 - uWSGI worker 1 screams: UAAAAAAH my master disconnected: i will kill myself !!!
*** Starting uWSGI 2.0.17.1 (64bit) on [Tue Aug 28 15:41:34 2018] ***
compiled with version: 4.8.5 20150623 (Red Hat 4.8.5-16) on 27 August 2018 07:28:24
os: Linux-3.10.0-693.2.2.el7.x86_64 #1 SMP Tue Sep 12 22:26:13 UTC 2017
nodename: izm5e47p6szixv6rgotzl2z
machine: x86_64
clock source: unix
pcre jit disabled
detected number of CPU cores: 1
current working directory: /data/cycle
writing pidfile to /data/cycle/script/uwsgi.pid
detected binary path: /usr/local/bin/uwsgi
*** WARNING: you are running uWSGI as root !!! (use the --uid flag) *** 
chdir() to /data/cycle/
your processes number limit is 1879
your memory page size is 4096 bytes
detected max file descriptor number: 65535
building mime-types dictionary from file /etc/mime.types...0 entry found
lock engine: pthread robust mutexes
thunder lock: enabled
uwsgi socket 0 bound to TCP address 127.0.0.1:8001 fd 3
*** WARNING: you are running uWSGI as root !!! (use the --uid flag) *** 
Python version: 3.6.5 (default, Jul 31 2018, 15:09:54)  [GCC 4.8.5 20150623 (Red Hat 4.8.5-16)]
Python main interpreter initialized at 0x1a45950
*** WARNING: you are running uWSGI as root !!! (use the --uid flag) *** 
python threads support enabled
your server socket listen backlog is limited to 100 connections
your mercy for graceful operations on workers is 60 seconds
mapped 162224 bytes (158 KB) for 1 cores
*** Operational MODE: single process ***
Traceback (most recent call last):
  File "./cycle/wsgi.py", line 16, in <module>
    application = get_wsgi_application()
  File "/usr/local/lib/python3.6/site-packages/django/core/wsgi.py", line 12, in get_wsgi_application
    django.setup(set_prefix=False)
  File "/usr/local/lib/python3.6/site-packages/django/__init__.py", line 24, in setup
    apps.populate(settings.INSTALLED_APPS)
  File "/usr/local/lib/python3.6/site-packages/django/apps/registry.py", line 120, in populate
    app_config.ready()
  File "/usr/local/lib/python3.6/site-packages/xadmin/apps.py", line 14, in ready
    self.module.autodiscover()
  File "/usr/local/lib/python3.6/site-packages/xadmin/__init__.py", line 49, in autodiscover
    register_builtin_plugins(site)
  File "/usr/local/lib/python3.6/site-packages/xadmin/plugins/__init__.py", line 41, in register_builtin_plugins
    [import_module('xadmin.plugins.%s' % plugin) for plugin in PLUGINS if plugin not in exclude_plugins]
  File "/usr/local/lib/python3.6/site-packages/xadmin/plugins/__init__.py", line 41, in <listcomp>
    [import_module('xadmin.plugins.%s' % plugin) for plugin in PLUGINS if plugin not in exclude_plugins]
  File "/usr/local/lib/python3.6/importlib/__init__.py", line 126, in import_module
    return _bootstrap._gcd_import(name[level:], package, level)
  File "/usr/local/lib/python3.6/site-packages/xadmin/plugins/themes.py", line 3, in <module>
    import httplib2
  File "/usr/local/lib/python3.6/site-packages/httplib2/__init__.py", line 51, in <module>
    import ssl
  File "/usr/local/lib/python3.6/ssl.py", line 101, in <module>
    import _ssl             # if we can't import it, let the error propagate
ModuleNotFoundError: No module named '_ssl'
unable to load app 0 (mountpoint='') (callable not found or import error)
*** no app loaded. going in full dynamic mode ***
*** WARNING: you are running uWSGI as root !!! (use the --uid flag) *** 
*** uWSGI is running in multiple interpreter mode ***
spawned uWSGI master process (pid: 6590)
spawned uWSGI worker 1 (pid: 6593, cores: 1)
--- no python application found, check your startup logs for errors ---
[pid: 6593|app: -1|req: -1/1] 138.0.227.107 () {32 vars in 470 bytes} [Tue Aug 28 15:43:20 2018] GET / => generated 21 bytes in 0 msecs (HTTP/1.1 500) 2 headers in 83 bytes (0 switches on core 0)
=======
*** Starting uWSGI 2.0.17.1 (64bit) on [Tue Aug 28 15:28:53 2018] ***
compiled with version: 4.2.1 Compatible Apple LLVM 9.1.0 (clang-902.0.39.1) on 06 August 2018 12:28:47
os: Darwin-17.7.0 Darwin Kernel Version 17.7.0: Thu Jun 21 22:53:14 PDT 2018; root:xnu-4570.71.2~1/RELEASE_X86_64
nodename: MacBook-Pro.local
machine: x86_64
clock source: unix
pcre jit disabled
detected number of CPU cores: 4
current working directory: /Users/zhang/Desktop
writing pidfile to /Users/zhang/Documents/Python/cycle/script/uwsgi.pid
detected binary path: /usr/local/bin/uwsgi
chdir() to /Users/zhang/Documents/Python/cycle/
your processes number limit is 709
your memory page size is 4096 bytes
detected max file descriptor number: 7168
building mime-types dictionary from file /etc/apache2/mime.types...1003 entry found
lock engine: OSX spinlocks
thunder lock: enabled
uwsgi socket 0 bound to TCP address 127.0.0.1:8001 fd 3
Python version: 3.6.5 (default, May 25 2018, 19:18:58)  [GCC 4.2.1 Compatible Apple LLVM 9.1.0 (clang-902.0.39.1)]
Python main interpreter initialized at 0x7f84fe812e00
python threads support enabled
your server socket listen backlog is limited to 100 connections
your mercy for graceful operations on workers is 60 seconds
mapped 162160 bytes (158 KB) for 1 cores
*** Operational MODE: single process ***
4a:00:06:1d:04:80
WSGI app 0 (mountpoint='') ready in 1 seconds on interpreter 0x7f84fe812e00 pid: 91180 (default app)
*** uWSGI is running in multiple interpreter mode ***
spawned uWSGI master process (pid: 91180)
spawned uWSGI worker 1 (pid: 91192, cores: 1)
invalid request block size: 21573 (max 4096)...skip
invalid request block size: 21573 (max 4096)...skip
invalid request block size: 21573 (max 4096)...skip
invalid request block size: 21573 (max 4096)...skip
invalid request block size: 21573 (max 4096)...skip
>>>>>>> 7a532e6d578e361d258f5867c0632f92f6b8ae0e
*** Starting uWSGI 2.0.17.1 (64bit) on [Tue Aug 28 15:49:30 2018] ***
compiled with version: 4.8.5 20150623 (Red Hat 4.8.5-16) on 27 August 2018 07:28:24
os: Linux-3.10.0-693.2.2.el7.x86_64 #1 SMP Tue Sep 12 22:26:13 UTC 2017
nodename: izm5e47p6szixv6rgotzl2z
machine: x86_64
clock source: unix
pcre jit disabled
detected number of CPU cores: 1
current working directory: /data/cycle
writing pidfile to /data/cycle/script/uwsgi.pid
detected binary path: /usr/local/bin/uwsgi
*** WARNING: you are running uWSGI as root !!! (use the --uid flag) *** 
chdir() to /data/cycle/
your processes number limit is 1879
your memory page size is 4096 bytes
detected max file descriptor number: 65535
building mime-types dictionary from file /etc/mime.types...0 entry found
lock engine: pthread robust mutexes
thunder lock: enabled
uwsgi socket 0 bound to TCP address 127.0.0.1:8001 fd 3
*** WARNING: you are running uWSGI as root !!! (use the --uid flag) *** 
Python version: 3.6.5 (default, Jul 31 2018, 15:09:54)  [GCC 4.8.5 20150623 (Red Hat 4.8.5-16)]
Python main interpreter initialized at 0x23e7950
*** WARNING: you are running uWSGI as root !!! (use the --uid flag) *** 
python threads support enabled
your server socket listen backlog is limited to 100 connections
your mercy for graceful operations on workers is 60 seconds
mapped 162224 bytes (158 KB) for 1 cores
*** Operational MODE: single process ***
Traceback (most recent call last):
  File "./cycle/wsgi.py", line 16, in <module>
    application = get_wsgi_application()
  File "/usr/local/lib/python3.6/site-packages/django/core/wsgi.py", line 12, in get_wsgi_application
    django.setup(set_prefix=False)
  File "/usr/local/lib/python3.6/site-packages/django/__init__.py", line 24, in setup
    apps.populate(settings.INSTALLED_APPS)
  File "/usr/local/lib/python3.6/site-packages/django/apps/registry.py", line 120, in populate
    app_config.ready()
  File "/usr/local/lib/python3.6/site-packages/xadmin/apps.py", line 14, in ready
    self.module.autodiscover()
  File "/usr/local/lib/python3.6/site-packages/xadmin/__init__.py", line 49, in autodiscover
    register_builtin_plugins(site)
  File "/usr/local/lib/python3.6/site-packages/xadmin/plugins/__init__.py", line 41, in register_builtin_plugins
    [import_module('xadmin.plugins.%s' % plugin) for plugin in PLUGINS if plugin not in exclude_plugins]
  File "/usr/local/lib/python3.6/site-packages/xadmin/plugins/__init__.py", line 41, in <listcomp>
    [import_module('xadmin.plugins.%s' % plugin) for plugin in PLUGINS if plugin not in exclude_plugins]
  File "/usr/local/lib/python3.6/importlib/__init__.py", line 126, in import_module
    return _bootstrap._gcd_import(name[level:], package, level)
  File "/usr/local/lib/python3.6/site-packages/xadmin/plugins/themes.py", line 3, in <module>
    import httplib2
  File "/usr/local/lib/python3.6/site-packages/httplib2/__init__.py", line 51, in <module>
    import ssl
  File "/usr/local/lib/python3.6/ssl.py", line 101, in <module>
    import _ssl             # if we can't import it, let the error propagate
ModuleNotFoundError: No module named '_ssl'
unable to load app 0 (mountpoint='') (callable not found or import error)
*** no app loaded. going in full dynamic mode ***
*** WARNING: you are running uWSGI as root !!! (use the --uid flag) *** 
*** uWSGI is running in multiple interpreter mode ***
spawned uWSGI master process (pid: 7055)
spawned uWSGI worker 1 (pid: 7057, cores: 1)
